<?xml version="1.0" encoding="utf-8"?>
<!-- =================================================================================== -->
<!-- |    This document was autogenerated by xacro from panda_arm_hand.urdf.xacro      | -->
<!-- |    EDITING THIS FILE BY HAND IS NOT RECOMMENDED                                 | -->
<!-- =================================================================================== -->
<robot name="panda" xmlns:xacro="http://www.ros.org/wiki/xacro">
<link name="root"/>
  <link name="root1"/>
  <link name="root2"/>
  <link name="root3"/>
  <link name="root4"/>
  <link name="root5"/>
  <link name="root6"/>
  <joint name="x_axis_joint" type="prismatic">
    <parent link="root"/>
    <child link="root1"/>
    <axis xyz="1 0 0"/>
    <limit lower="-10" upper="10" velocity="0.50"/>
    <dynamics damping="10.0" friction="10"/>
  </joint>
  <joint name="y_axis_joint" type="prismatic">
    <parent link="root1"/>
    <child link="root2"/>
    <axis xyz="0 1 0"/>
    <limit lower="-10" upper="10" velocity="0.50"/>
    <dynamics damping="10.0" friction="10"/>
  </joint>
  <joint name="z_axis_joint" type="prismatic">
    <parent link="root2"/>
    <child link="root3"/>
    <axis xyz="0 0 1"/>
    <limit lower="-10" upper="10" velocity="0.50"/>
    <dynamics damping="10.0" friction="10"/>
  </joint>
  <!-- <joint name="x_rotation_joint" type="continuous">
    <parent link="root3"/>
    <child link="root4"/>
    <axis xyz="1 0 0"/>
    <dynamics damping="10.0" friction="1"/>
  </joint>
  <joint name="y_rotation_joint" type="continuous">
    <parent link="root4"/>
    <child link="root5"/>
    <axis xyz="0 1 0"/>
    <dynamics damping="10.0" friction="1"/>
  </joint>
  <joint name="z_rotation_joint" type="continuous">
    <parent link="root5"/>
    <child link="root6"/>
    <axis xyz="0 0 1"/>
    <dynamics damping="10.0" friction="1"/>
  </joint> -->
  <joint name="x_rotation_joint" type="fixed">
    <parent link="root3"/>
    <child link="root4"/>
    <axis xyz="1 0 0"/>
    <origin rpy="0 0 0" xyz="0 0 0.0"/>
    <dynamics damping="10.0" friction="1"/>
  </joint>
  <joint name="y_rotation_joint" type="fixed">
    <parent link="root4"/>
    <child link="root5"/>
    <axis xyz="0 1 0"/>
    <origin rpy="0 0 0" xyz="0 0 0.0"/>
    <dynamics damping="10.0" friction="1"/>
  </joint>
  <joint name="z_rotation_joint" type="fixed">
    <parent link="root5"/>
    <child link="root6"/>
    <axis xyz="0 0 1"/>
    <origin rpy="0 0 0" xyz="0 0 0.0"/>
    <dynamics damping="10.0" friction="1"/>
  </joint>
  <joint name="right_ee_fixed_joint" type="fixed">
    <parent link="root6"/>
    <child link="right_ee_link"/>
  </joint>
  <link name="right_ee_link"/>
  <joint name="panda_hand_joint" type="fixed">
    <parent link="right_ee_link"/>
    <child link="panda_hand"/>
    <origin rpy="0 3.1415926 0" xyz="0 0 0"/>
  </joint>
  <link name="panda_hand">
    <visual>
      <geometry>
        <mesh filename="franka_description/meshes/visual/hand.dae"/>
      </geometry>
    </visual>
    <collision>
      <geometry>
        <mesh filename="franka_description/meshes/collision/hand.stl"/>
      </geometry>
    </collision>
  </link>
  <link name="panda_leftfinger">
    <visual>
      <geometry>
        <mesh filename="franka_description/meshes/visual/finger.dae"/>
      </geometry>
    </visual>
    <collision>
      <origin xyz="0 0.0072 0.044862" />
      <geometry>
        <box size="0.017088 0.01466 0.017088"/>
      </geometry>
    </collision>
    <collision>
      <origin xyz="0 0.018361 0.011482" />
      <geometry>
        <box size="0.020466 0.015156 0.01515"/>
      </geometry>
    </collision>
    <collision>
      <origin xyz="0 0.016462 0.027801" rpy="0.5280214399228524 0 0" />
      <geometry>
        <box size="0.020984 0.006538 0.02391"/>
      </geometry>
    </collision>
  </link>
  <link name="panda_rightfinger">
    <visual>
      <origin rpy="0 0 3.14159265359" xyz="0 0 0"/>
      <geometry>
        <mesh filename="franka_description/meshes/visual/finger.dae"/>
      </geometry>
    </visual>
    <collision>
      <origin xyz="0 -0.0072 0.044862" />
      <geometry>
        <box size="0.017088 0.01466 0.017088"/>
      </geometry>
    </collision>
    <collision>
      <origin xyz="0 -0.018361 0.011482" />
      <geometry>
        <box size="0.020466 0.015156 0.01515"/>
      </geometry>
    </collision>
    <collision>
      <origin xyz="0 -0.016462 0.027801" rpy="0.5280214399228524 0 3.14159265359" />
      <geometry>
        <box size="0.020984 0.006538 0.02391"/>
      </geometry>
    </collision>
  </link>
  <joint name="panda_finger_joint1" type="prismatic">
    <parent link="panda_hand"/>
    <child link="panda_leftfinger"/>
    <origin rpy="0 0 0" xyz="0 0 0.0584"/>
    <axis xyz="0 1 0"/>
    <limit effort="20" lower="0.0" upper="0.04" velocity="0.2"/>
  </joint>
  <joint name="panda_finger_joint2" type="prismatic">
    <parent link="panda_hand"/>
    <child link="panda_rightfinger"/>
    <origin rpy="0 0 0" xyz="0 0 0.0584"/>
    <axis xyz="0 -1 0"/>
    <limit effort="20" lower="0.0" upper="0.04" velocity="0.2"/>
    <mimic joint="panda_finger_joint1"/>
  </joint>
  <link name="grasp_site" />
  <joint name="grasp_site_joint" type="fixed">
    <origin rpy="0 0 0" xyz="0 0 0.103" />
    <parent link="panda_hand" />
    <child link="grasp_site" />
  </joint>
</robot>
